Workbook

Sheet 00_INICIO
A1: CARNE PREMIUM ERP
A3: Nueva Venta
A4: Clientes
A5: Productos
A6: Caja
A7: Stock
A8: Dashboard
A9: Configuración

Sheet 01_PARAMETROS
A1: Parametro | B1: Valor
A2: TipoPrecioDefault | B2: Minorista
A3: Moneda | B3: ARS
A4: Empresa | B4: Carne Premium ERP
A6: Vendedor por defecto
A7: IVA | B7: 21
A8: Medio de pago | B8: Efectivo

Sheet 02_CATALOGOS
A1: TiposPrecio | B1: Estados | C1: MediosPago
A2: Minorista | B2: Activo | C2: Efectivo
A3: Mayorista | B3: Inactivo | C3: Transferencia
A4: Especial | C4: Cuenta Corriente

Sheet 03_CLIENTES
A1: ClienteID | B1: Nombre | C1: Telefono | D1: Direccion | E1: Estado | F1: FechaAlta | G1: Observaciones
A2: =IF(B2="","","CLI"&TEXT(ROW()-1,"000000")) -> CLI000001 | B2: Adela Igarzabal | C2: 54 911-3261-4129
A3: =IF(B3="","","CLI"&TEXT(ROW()-1,"000000")) -> CLI000002 | B3: Ale Silveyra | C3: 54 911-5720-1983 | D3: Victoria Ocampo 738, Beccar | G3: Coordinar con Silvina
A4: =IF(B4="","","CLI"&TEXT(ROW()-1,"000000")) -> CLI000003 | B4: Ana del Pino
A5: =IF(B5="","","CLI"&TEXT(ROW()-1,"000000")) -> CLI000004 | B5: Annette | C5: 54 911-6227-8629 | D5: Suipacha 2365, Beccar
A6: =IF(B6="","","CLI"&TEXT(ROW()-1,"000000")) -> CLI000005 | B6: Bettina Helvadjian | C6: 54 911-4889-5676 | D6: Diagonal Tucumán 671, Martinez
A7: =IF(B7="","","CLI"&TEXT(ROW()-1,"000000")) -> CLI000006 | B7: Carlos Rivero
A8: =IF(B8="","","CLI"&TEXT(ROW()-1,"000000")) -> CLI000007 | B8: Carola Alfonzo | C8: 54 911-6369-0104 | G8: Mamá Fran Rodillo
A9: =IF(B9="","","CLI"&TEXT(ROW()-1,"000000")) -> CLI000008 | B9: Cristina Igarzabal | C9: 54 911-3245-6070
A10: =IF(B10="","","CLI"&TEXT(ROW()-1,"000000")) -> CLI000009 | B10: Delia
A11: =IF(B11="","","CLI"&TEXT(ROW()-1,"000000")) -> CLI000010 | B11: Diego
A12: =IF(B12="","","CLI"&TEXT(ROW()-1,"000000")) -> CLI000011 | B12: Diego Gonzalez Bonorino | C12: 54 911-4041-3480 | D12: Nicolás Avellaneda 2262, San Isidro
A13: =IF(B13="","","CLI"&TEXT(ROW()-1,"000000")) -> CLI000012 | B13: Ezequiel | C13: 54 911-6589-4002 | D13: Barrio Sunny, Tigre | G13: Lote 24
A14: =IF(B14="","","CLI"&TEXT(ROW()-1,"000000")) -> CLI000013 | B14: Fran Rodillo
A15: =IF(B15="","","CLI"&TEXT(ROW()-1,"000000")) -> CLI000014 | B15: Gastón
A16: =IF(B16="","","CLI"&TEXT(ROW()-1,"000000")) -> CLI000015 | B16: Gastón Uzin | C16: 54 911-3245-7669
A17: =IF(B17="","","CLI"&TEXT(ROW()-1,"000000")) -> CLI000016 | B17: Inés Igarzabal | C17: 54 911-6494-8444 | D17: Jacinto Diaz 2080, San Isidro
A18: =IF(B18="","","CLI"&TEXT(ROW()-1,"000000")) -> CLI000017 | B18: Isabel Lopez Lacarrere | C18: 54 911-4444-7034 | D18: Barrio Sunny, Tigre | G18: Lote 49
A19: =IF(B19="","","CLI"&TEXT(ROW()-1,"000000")) -> CLI000018 | B19: Jaime Lorenzo
A20: =IF(B20="","","CLI"&TEXT(ROW()-1,"000000")) -> CLI000019 | B20: Jime Gonzalez Mathys | C20: 54 911-3090-2166 | D20: Rosario de Santa Fe 649, Beccar
A21: =IF(B21="","","CLI"&TEXT(ROW()-1,"000000")) -> CLI000020 | B21: Joaquin Reichart | C21: 56 9 9851-6389 | D21: Bolivar 290, Beccar | G21: Casa de los padres
A22: =IF(B22="","","CLI"&TEXT(ROW()-1,"000000")) -> CLI000021 | B22: Juan Sw
A23: =IF(B23="","","CLI"&TEXT(ROW()-1,"000000")) -> CLI000022 | B23: Juanito | C23: 54 911-6655-1994
A24: =IF(B24="","","CLI"&TEXT(ROW()-1,"000000")) -> CLI000023 | B24: Juan Martín Duclos | C24: 54 911-3209-0844
A25: =IF(B25="","","CLI"&TEXT(ROW()-1,"000000")) -> CLI000024 | B25: Laura Guidi | C25: 54 911-3930-7437 | D25: J. F. Kennedy, Victoria | G25: Costurera/Limpieza
A26: =IF(B26="","","CLI"&TEXT(ROW()-1,"000000")) -> CLI000025 | B26: Laura Igarzabal
A27: =IF(B27="","","CLI"&TEXT(ROW()-1,"000000")) -> CLI000026 | B27: Lourdes
A28: =IF(B28="","","CLI"&TEXT(ROW()-1,"000000")) -> CLI000027 | B28: Maria Eizayaga
A29: =IF(B29="","","CLI"&TEXT(ROW()-1,"000000")) -> CLI000028 | B29: Mariano
A30: =IF(B30="","","CLI"&TEXT(ROW()-1,"000000")) -> CLI000029 | B30: Matias de Blasi | C30: 54 911-6299-2667
A31: =IF(B31="","","CLI"&TEXT(ROW()-1,"000000")) -> CLI000030 | B31: Matias Sonzini | C31: 54 911-3593-2039 | D31: Ohiggins 450, San Isidro | G31: 1 "A"
A32: =IF(B32="","","CLI"&TEXT(ROW()-1,"000000")) -> CLI000031 | B32: Matias Ureta
A33: =IF(B33="","","CLI"&TEXT(ROW()-1,"000000")) -> CLI000032 | B33: Muncha | C33: 54 911-4416-8375 | D33: Murature 732, San Isidro | G33: Mamá de Nacho y Juan Ortega
A34: =IF(B34="","","CLI"&TEXT(ROW()-1,"000000")) -> CLI000033 | B34: Pato O'Reilly
A35: =IF(B35="","","CLI"&TEXT(ROW()-1,"000000")) -> CLI000034 | B35: Patricio Cabrini
A36: =IF(B36="","","CLI"&TEXT(ROW()-1,"000000")) -> CLI000035 | B36: Peter | C36: 54 911-5452-4573 | D36: Vicente Fidel López 388, Martinez | G36: 2 "A"
A37: =IF(B37="","","CLI"&TEXT(ROW()-1,"000000")) -> CLI000036 | B37: Rochi Melazza
A38: =IF(B38="","","CLI"&TEXT(ROW()-1,"000000")) -> CLI000037 | B38: Rodolfo Melazza
A39: =IF(B39="","","CLI"&TEXT(ROW()-1,"000000")) -> CLI000038 | B39: Santi Breide | C39: 54 911-3904-5214
A40: =IF(B40="","","CLI"&TEXT(ROW()-1,"000000")) -> CLI000039 | B40: Sonia Haddad | C40: 507 6354-0567 | D40: Monseñor Alberti 474, San Isidro | G40: 3 "A"
...

Sheet 04_PRODUCTOS
A1: ProductoID | B1: Producto | C1: Categoria | D1: Costo | E1: Precio Minorista | F1: Precio Mayorista | G1: Precio Especial | H1: Oferta | I1: Ganancia$ | J1: Ganancia% | K1: Estado
A2: =IF(B2="","","PRO"&TEXT(ROW()-1,"000000")) -> PRO000001 | B2: Bife de Chorizo | C2: Vacuno | D2: 20000 | E2: 22000 | I2: =IF(AND(D2<>"",E2<>""),E2-D2,"") -> 2000 | J2: =IFERROR((E2-D2)/E2,"") -> 0.090909091 | K2: Activo
A3: =IF(B3="","","PRO"&TEXT(ROW()-1,"000000")) -> PRO000002 | B3: Coita de Cuadril | C3: Vacuno | D3: 21000 | E3: 23000 | I3: =IF(AND(D3<>"",E3<>""),E3-D3,"") -> 2000 | J3: =IFERROR((E3-D3)/E3,"") -> 0.086956522 | K3: Activo
A4: =IF(B4="","","PRO"&TEXT(ROW()-1,"000000")) -> PRO000003 | B4: Lomo | C4: Vacuno | D4: 27000 | E4: 29000 | I4: =IF(AND(D4<>"",E4<>""),E4-D4,"") -> 2000 | J4: =IFERROR((E4-D4)/E4,"") -> 0.068965517 | K4: Activo
A5: =IF(B5="","","PRO"&TEXT(ROW()-1,"000000")) -> PRO000004 | B5: Nalga Feteada | C5: Vacuno | D5: 19000 | E5: 22000 | I5: =IF(AND(D5<>"",E5<>""),E5-D5,"") -> 3000 | J5: =IFERROR((E5-D5)/E5,"") -> 0.13636364 | K5: Activo
A6: =IF(B6="","","PRO"&TEXT(ROW()-1,"000000")) -> PRO000005 | B6: Nalga sin Tapa | C6: Vacuno | D6: 17500 | E6: 19500 | I6: =IF(AND(D6<>"",E6<>""),E6-D6,"") -> 2000 | J6: =IFERROR((E6-D6)/E6,"") -> 0.1025641 | K6: Activo
A7: =IF(B7="","","PRO"&TEXT(ROW()-1,"000000")) -> PRO000006 | B7: Peceto | C7: Vacuno | D7: 19000 | E7: 21000 | I7: =IF(AND(D7<>"",E7<>""),E7-D7,"") -> 2000 | J7: =IFERROR((E7-D7)/E7,"") -> 0.095238095 | K7: Activo
A8: =IF(B8="","","PRO"&TEXT(ROW()-1,"000000")) -> PRO000007 | B8: Peceto Feteado | C8: Vacuno | D8: 19000 | E8: 22000 | I8: =IF(AND(D8<>"",E8<>""),E8-D8,"") -> 3000 | J8: =IFERROR((E8-D8)/E8,"") -> 0.13636364 | K8: Activo
A9: =IF(B9="","","PRO"&TEXT(ROW()-1,"000000")) -> PRO000008 | B9: Picada Especial | C9: Vacuno | D9: 14000 | E9: 16000 | I9: =IF(AND(D9<>"",E9<>""),E9-D9,"") -> 2000 | J9: =IFERROR((E9-D9)/E9,"") -> 0.125 | K9: Activo
A10: =IF(B10="","","PRO"&TEXT(ROW()-1,"000000")) -> PRO000009 | B10: Picaña | C10: Vacuno | D10: 19000 | E10: 23000 | I10: =IF(AND(D10<>"",E10<>""),E10-D10,"") -> 4000 | J10: =IFERROR((E10-D10)/E10,"") -> 0.17391304 | K10: Activo
A11: =IF(B11="","","PRO"&TEXT(ROW()-1,"000000")) -> PRO000010 | B11: Vacío | C11: Vacuno | D11: 17000 | E11: 20000 | I11: =IF(AND(D11<>"",E11<>""),E11-D11,"") -> 3000 | J11: =IFERROR((E11-D11)/E11,"") -> 0.15 | K11: Activo
A12: =IF(B12="","","PRO"&TEXT(ROW()-1,"000000")) -> PRO000011 | B12: Vacío Fraccionado | C12: Vacuno | D12: 17000 | E12: 22000 | I12: =IF(AND(D12<>"",E12<>""),E12-D12,"") -> 5000 | J12: =IFERROR((E12-D12)/E12,"") -> 0.22727273 | K12: Activo
A13: =IF(B13="","","PRO"&TEXT(ROW()-1,"000000")) -> PRO000012 | B13: Ojo de Bife | C13: Vacuno | E13: 29000 | I13: =IF(AND(D13<>"",E13<>""),E13-D13,"") | J13: =IFERROR((E13-D13)/E13,"") -> 1 | K13: Activo
A14: =IF(B14="","","PRO"&TEXT(ROW()-1,"000000")) | I14: =IF(AND(D14<>"",E14<>""),E14-D14,"") | J14: =IFERROR((E14-D14)/E14,"")
A15: =IF(B15="","","PRO"&TEXT(ROW()-1,"000000")) | I15: =IF(AND(D15<>"",E15<>""),E15-D15,"") | J15: =IFERROR((E15-D15)/E15,"")
A16: =IF(B16="","","PRO"&TEXT(ROW()-1,"000000")) | I16: =IF(AND(D16<>"",E16<>""),E16-D16,"") | J16: =IFERROR((E16-D16)/E16,"")
A17: =IF(B17="","","PRO"&TEXT(ROW()-1,"000000")) | I17: =IF(AND(D17<>"",E17<>""),E17-D17,"") | J17: =IFERROR((E17-D17)/E17,"")
A18: =IF(B18="","","PRO"&TEXT(ROW()-1,"000000")) | I18: =IF(AND(D18<>"",E18<>""),E18-D18,"") | J18: =IFERROR((E18-D18)/E18,"")
A19: =IF(B19="","","PRO"&TEXT(ROW()-1,"000000")) | I19: =IF(AND(D19<>"",E19<>""),E19-D19,"") | J19: =IFERROR((E19-D19)/E19,"")
A20: =IF(B20="","","PRO"&TEXT(ROW()-1,"000000")) | I20: =IF(AND(D20<>"",E20<>""),E20-D20,"") | J20: =IFERROR((E20-D20)/E20,"")
A21: =IF(B21="","","PRO"&TEXT(ROW()-1,"000000")) | I21: =IF(AND(D21<>"",E21<>""),E21-D21,"") | J21: =IFERROR((E21-D21)/E21,"")
A22: =IF(B22="","","PRO"&TEXT(ROW()-1,"000000")) | I22: =IF(AND(D22<>"",E22<>""),E22-D22,"") | J22: =IFERROR((E22-D22)/E22,"")
A23: =IF(B23="","","PRO"&TEXT(ROW()-1,"000000")) | I23: =IF(AND(D23<>"",E23<>""),E23-D23,"") | J23: =IFERROR((E23-D23)/E23,"")
A24: =IF(B24="","","PRO"&TEXT(ROW()-1,"000000")) | I24: =IF(AND(D24<>"",E24<>""),E24-D24,"") | J24: =IFERROR((E24-D24)/E24,"")
A25: =IF(B25="","","PRO"&TEXT(ROW()-1,"000000")) | I25: =IF(AND(D25<>"",E25<>""),E25-D25,"") | J25: =IFERROR((E25-D25)/E25,"")
... A201: =IF(B201="","","PRO"&TEXT(ROW()-1,"000000")) | I201: =IF(AND(D201<>"",E201<>""),E201-D201,"") | J201: =IFERROR((E201-D201)/E201,"")
I202: =IF(AND(D202<>"",E202<>""),E202-D202,"") | J202: =IFERROR((E202-D202)/E202,"")
I203: =IF(AND(D203<>"",E203<>""),E203-D203,"") | J203: =IFERROR((E203-D203)/E203,"")
I204: =IF(AND(D204<>"",E204<>""),E204-D204,"") | J204: =IFERROR((E204-D204)/E204,"")
I205: =IF(AND(D205<>"",E205<>""),E205-D205,"") | J205: =IFERROR((E205-D205)/E205,"")
I206: =IF(AND(D206<>"",E206<>""),E206-D206,"") | J206: =IFERROR((E206-D206)/E206,"")
I207: =IF(AND(D207<>"",E207<>""),E207-D207,"") | J207: =IFERROR((E207-D207)/E207,"")
I208: =IF(AND(D208<>"",E208<>""),E208-D208,"") | J208: =IFERROR((E208-D208)/E208,"")
I209: =IF(AND(D209<>"",E209<>""),E209-D209,"") | J209: =IFERROR((E209-D209)/E209,"")
I210: =IF(AND(D210<>"",E210<>""),E210-D210,"") | J210: =IFERROR((E210-D210)/E210,"")
I211: =IF(AND(D211<>"",E211<>""),E211-D211,"") | J211: =IFERROR((E211-D211)/E211,"")
I212: =IF(AND(D212<>"",E212<>""),E212-D212,"") | J212: =IFERROR((E212-D212)/E212,"")
I213: =IF(AND(D213<>"",E213<>""),E213-D213,"") | J213: =IFERROR((E213-D213)/E213,"")
... I501: =IF(AND(D501<>"",E501<>""),E501-D501,"") | J501: =IFERROR((E501-D501)/E501,"")

Sheet 05_VENTAS
A1: VentaID | B1: Fecha | C1: Cliente | D1: TipoPrecio | E1: Producto | F1: Kg | G1: PrecioKg | H1: Importe | I1: Ganancia$ | J1: Ganancia%
A2: =IF(C2="","","VEN"&TEXT(ROW()-1,"000000")) -> VEN000001 | B2: 46204 | C2: Pato O'Reilly | D2: Minorista | E2: Picada Especial | F2: 3.4 | G2: =IFERROR(IF(D2="Mayorista",IF(VLOOKUP(E2,'04_PRODUCTOS'!B:F,5,FALSE)="",VLOOKUP(E2,'04_PRODUCTOS'!B:E,4,FALSE),VLOOKUP(E2,'04_PRODUCTOS'!B:F,5,FALSE)),IF(D2="Especial",IF(VLOOKUP(E2,'04_PRODUCTOS'!B:G,6,FALSE)="",VLOOKUP(E2,'04_PRODUCTOS'!B:E,4,FALSE),VLOOKUP(E2,'04_PRODUCTOS'!B:G,6,FALSE)),VLOOKUP(E2,'04_PRODUCTOS'!B:E,4,FALSE))),"") -> 16000 | H2: =IF(AND(F2<>"",G2<>""),F2*G2,"") -> 54400 | I2: =IFERROR(H2-(F2*VLOOKUP(E2,'04_PRODUCTOS'!B:D,3,FALSE)),"") -> 6800 | J2: =IFERROR(I2/H2,"") -> 0.125
A3: =IF(C3="","","VEN"&TEXT(ROW()-1,"000000")) -> VEN000002 | B3: 46204 | C3: Pato O'Reilly | D3: Minorista | E3: Nalga Feteada | F3: 1.1 | G3: =IFERROR(IF(D3="Mayorista",IF(VLOOKUP(E3,'04_PRODUCTOS'!B:F,5,FALSE)="",VLOOKUP(E3,'04_PRODUCTOS'!B:E,4,FALSE),VLOOKUP(E3,'04_PRODUCTOS'!B:F,5,FALSE)),IF(D3="Especial",IF(VLOOKUP(E3,'04_PRODUCTOS'!B:G,6,FALSE)="",VLOOKUP(E3,'04_PRODUCTOS'!B:E,4,FALSE),VLOOKUP(E3,'04_PRODUCTOS'!B:G,6,FALSE)),VLOOKUP(E3,'04_PRODUCTOS'!B:E,4,FALSE))),"") -> 22000 | H3: =IF(AND(F3<>"",G3<>""),F3*G3,"") -> 24200 | I3: =IFERROR(H3-(F3*VLOOKUP(E3,'04_PRODUCTOS'!B:D,3,FALSE)),"") -> 3300 | J3: =IFERROR(I3/H3,"") -> 0.13636364
A4: =IF(C4="","","VEN"&TEXT(ROW()-1,"000000")) -> VEN000003 | B4: 46204 | C4: Pato O'Reilly | D4: Minorista | E4: Coita de Cuadril | F4: 1.9 | G4: =IFERROR(IF(D4="Mayorista",IF(VLOOKUP(E4,'04_PRODUCTOS'!B:F,5,FALSE)="",VLOOKUP(E4,'04_PRODUCTOS'!B:E,4,FALSE),VLOOKUP(E4,'04_PRODUCTOS'!B:F,5,FALSE)),IF(D4="Especial",IF(VLOOKUP(E4,'04_PRODUCTOS'!B:G,6,FALSE)="",VLOOKUP(E4,'04_PRODUCTOS'!B:E,4,FALSE),VLOOKUP(E4,'04_PRODUCTOS'!B:G,6,FALSE)),VLOOKUP(E4,'04_PRODUCTOS'!B:E,4,FALSE))),"") -> 23000 | H4: =IF(AND(F4<>"",G4<>""),F4*G4,"") -> 43700 | I4: =IFERROR(H4-(F4*VLOOKUP(E4,'04_PRODUCTOS'!B:D,3,FALSE)),"") -> 3800 | J4: =IFERROR(I4/H4,"") -> 0.086956522
A5: =IF(C5="","","VEN"&TEXT(ROW()-1,"000000")) -> VEN000004 | B5: 46209 | C5: Santi Breide | D5: Minorista | E5: Nalga Feteada | F5: 2.2 | G5: =IFERROR(IF(D5="Mayorista",IF(VLOOKUP(E5,'04_PRODUCTOS'!B:F,5,FALSE)="",VLOOKUP(E5,'04_PRODUCTOS'!B:E,4,FALSE),VLOOKUP(E5,'04_PRODUCTOS'!B:F,5,FALSE)),IF(D5="Especial",IF(VLOOKUP(E5,'04_PRODUCTOS'!B:G,6,FALSE)="",VLOOKUP(E5,'04_PRODUCTOS'!B:E,4,FALSE),VLOOKUP(E5,'04_PRODUCTOS'!B:G,6,FALSE)),VLOOKUP(E5,'04_PRODUCTOS'!B:E,4,FALSE))),"") -> 22000 | H5: =IF(AND(F5<>"",G5<>""),F5*G5,"") -> 48400 | I5: =IFERROR(H5-(F5*VLOOKUP(E5,'04_PRODUCTOS'!B:D,3,FALSE)),"") -> 6600 | J5: =IFERROR(I5/H5,"") -> 0.13636364
A6: =IF(C6="","","VEN"&TEXT(ROW()-1,"000000")) -> VEN000005 | B6: 46210 | C6: Pato O'Reilly | D6: Minorista | E6: Vacío | F6: 4.5 | G6: =IFERROR(IF(D6="Mayorista",IF(VLOOKUP(E6,'04_PRODUCTOS'!B:F,5,FALSE)="",VLOOKUP(E6,'04_PRODUCTOS'!B:E,4,FALSE),VLOOKUP(E6,'04_PRODUCTOS'!B:F,5,FALSE)),IF(D6="Especial",IF(VLOOKUP(E6,'04_PRODUCTOS'!B:G,6,FALSE)="",VLOOKUP(E6,'04_PRODUCTOS'!B:E,4,FALSE),VLOOKUP(E6,'04_PRODUCTOS'!B:G,6,FALSE)),VLOOKUP(E6,'04_PRODUCTOS'!B:E,4,FALSE))),"") -> 20000 | H6: =IF(AND(F6<>"",G6<>""),F6*G6,"") -> 90000 | I6: =IFERROR(H6-(F6*VLOOKUP(E6,'04_PRODUCTOS'!B:D,3,FALSE)),"") -> 13500 | J6: =IFERROR(I6/H6,"") -> 0.15
A7: =IF(C7="","","VEN"&TEXT(ROW()-1,"000000")) -> VEN000006 | B7: 46210 | C7: Tomas Koch | D7: Minorista | E7: Lomo | F7: 8.1 | G7: =IFERROR(IF(D7="Mayorista",IF(VLOOKUP(E7,'04_PRODUCTOS'!B:F,5,FALSE)="",VLOOKUP(E7,'04_PRODUCTOS'!B:E,4,FALSE),VLOOKUP(E7,'04_PRODUCTOS'!B:F,5,FALSE)),IF(D7="Especial",IF(VLOOKUP(E7,'04_PRODUCTOS'!B:G,6,FALSE)="",VLOOKUP(E7,'04_PRODUCTOS'!B:E,4,FALSE),VLOOKUP(E7,'04_PRODUCTOS'!B:G,6,FALSE)),VLOOKUP(E7,'04_PRODUCTOS'!B:E,4,FALSE))),"") -> 29000 | H7: =IF(AND(F7<>"",G7<>""),F7*G7,"") -> 234900 | I7: =IFERROR(H7-(F7*VLOOKUP(E7,'04_PRODUCTOS'!B:D,3,FALSE)),"") -> 16200 | J7: =IFERROR(I7/H7,"") -> 0.068965517
A8: =IF(C8="","","VEN"&TEXT(ROW()-1,"000000")) -> VEN000007 | B8: 46210 | C8: Tomas Koch | D8: Minorista | E8: Nalga Feteada | F8: 2.5 | G8: =IFERROR(IF(D8="Mayorista",IF(VLOOKUP(E8,'04_PRODUCTOS'!B:F,5,FALSE)="",VLOOKUP(E8,'04_PRODUCTOS'!B:E,4,FALSE),VLOOKUP(E8,'04_PRODUCTOS'!B:F,5,FALSE)),IF(D8="Especial",IF(VLOOKUP(E8,'04_PRODUCTOS'!B:G,6,FALSE)="",VLOOKUP(E8,'04_PRODUCTOS'!B:E,4,FALSE),VLOOKUP(E8,'04_PRODUCTOS'!B:G,6,FALSE)),VLOOKUP(E8,'04_PRODUCTOS'!B:E,4,FALSE))),"") -> 22000 | H8: =IF(AND(F8<>"",G8<>""),F8*G8,"") -> 55000 | I8: =IFERROR(H8-(F8*VLOOKUP(E8,'04_PRODUCTOS'!B:D,3,FALSE)),"") -> 7500 | J8: =IFERROR(I8/H8,"") -> 0.13636364
A9: =IF(C9="","","VEN"&TEXT(ROW()-1,"000000")) -> VEN000008 | B9: 46210 | C9: Tomas Koch | D9: Minorista | E9: Vacío | F9: 3.1 | G9: =IFERROR(IF(D9="Mayorista",IF(VLOOKUP(E9,'04_PRODUCTOS'!B:F,5,FALSE)="",VLOOKUP(E9,'04_PRODUCTOS'!B:E,4,FALSE),VLOOKUP(E9,'04_PRODUCTOS'!B:F,5,FALSE)),IF(D9="Especial",IF(VLOOKUP(E9,'04_PRODUCTOS'!B:G,6,FALSE)="",VLOOKUP(E9,'04_PRODUCTOS'!B:E,4,FALSE),VLOOKUP(E9,'04_PRODUCTOS'!B:G,6,FALSE)),VLOOKUP(E9,'04_PRODUCTOS'!B:E,4,FALSE))),"") -> 20000 | H9: =IF(AND(F9<>"",G9<>""),F9*G9,"") -> 62000 | I9: =IFERROR(H9-(F9*VLOOKUP(E9,'04_PRODUCTOS'!B:D,3,FALSE)),"") -> 9300 | J9: =IFERROR(I9/H9,"") -> 0.15
A10: =IF(C10="","","VEN"&TEXT(ROW()-1,"000000")) | B10: =IF(C10="","",TODAY()) | G10: =IFERROR(IF(D10="Mayorista",IF(VLOOKUP(E10,'04_PRODUCTOS'!B:F,5,FALSE)="",VLOOKUP(E10,'04_PRODUCTOS'!B:E,4,FALSE),VLOOKUP(E10,'04_PRODUCTOS'!B:F,5,FALSE)),IF(D10="Especial",IF(VLOOKUP(E10,'04_PRODUCTOS'!B:G,6,FALSE)="",VLOOKUP(E10,'04_PRODUCTOS'!B:E,4,FALSE),VLOOKUP(E10,'04_PRODUCTOS'!B:G,6,FALSE)),VLOOKUP(E10,'04_PRODUCTOS'!B:E,4,FALSE))),"") | H10: =IF(AND(F10<>"",G10<>""),F10*G10,"") | I10: =IFERROR(H10-(F10*VLOOKUP(E10,'04_PRODUCTOS'!B:D,3,FALSE)),"") | J10: =IFERROR(I10/H10,"")
A11: =IF(C11="","","VEN"&TEXT(ROW()-1,"000000")) | B11: =IF(C11="","",TODAY()) | G11: =IFERROR(IF(D11="Mayorista",IF(VLOOKUP(E11,'04_PRODUCTOS'!B:F,5,FALSE)="",VLOOKUP(E11,'04_PRODUCTOS'!B:E,4,FALSE),VLOOKUP(E11,'04_PRODUCTOS'!B:F,5,FALSE)),IF(D11="Especial",IF(VLOOKUP(E11,'04_PRODUCTOS'!B:G,6,FALSE)="",VLOOKUP(E11,'04_PRODUCTOS'!B:E,4,FALSE),VLOOKUP(E11,'04_PRODUCTOS'!B:G,6,FALSE)),VLOOKUP(E11,'04_PRODUCTOS'!B:E,4,FALSE))),"") | H11: =IF(AND(F11<>"",G11<>""),F11*G11,"") | I11: =IFERROR(H11-(F11*VLOOKUP(E11,'04_PRODUCTOS'!B:D,3,FALSE)),"") | J11: =IFERROR(I11/H11,"")
A12: =IF(C12="","","VEN"&TEXT(ROW()-1,"000000")) | B12: =IF(C12="","",TODAY()) | G12: =IFERROR(IF(D12="Mayorista",IF(VLOOKUP(E12,'04_PRODUCTOS'!B:F,5,FALSE)="",VLOOKUP(E12,'04_PRODUCTOS'!B:E,4,FALSE),VLOOKUP(E12,'04_PRODUCTOS'!B:F,5,FALSE)),IF(D12="Especial",IF(VLOOKUP(E12,'04_PRODUCTOS'!B:G,6,FALSE)="",VLOOKUP(E12,'04_PRODUCTOS'!B:E,4,FALSE),VLOOKUP(E12,'04_PRODUCTOS'!B:G,6,FALSE)),VLOOKUP(E12,'04_PRODUCTOS'!B:E,4,FALSE))),"") | H12: =IF(AND(F12<>"",G12<>""),F12*G12,"") | I12: =IFERROR(H12-(F12*VLOOKUP(E12,'04_PRODUCTOS'!B:D,3,FALSE)),"") | J12: =IFERROR(I12/H12,"")
A13: =IF(C13="","","VEN"&TEXT(ROW()-1,"000000")) | B13: =IF(C13="","",TODAY()) | G13: =IFERROR(IF(D13="Mayorista",IF(VLOOKUP(E13,'04_PRODUCTOS'!B:F,5,FALSE)="",VLOOKUP(E13,'04_PRODUCTOS'!B:E,4,FALSE),VLOOKUP(E13,'04_PRODUCTOS'!B:F,5,FALSE)),IF(D13="Especial",IF(VLOOKUP(E13,'04_PRODUCTOS'!B:G,6,FALSE)="",VLOOKUP(E13,'04_PRODUCTOS'!B:E,4,FALSE),VLOOKUP(E13,'04_PRODUCTOS'!B:G,6,FALSE)),VLOOKUP(E13,'04_PRODUCTOS'!B:E,4,FALSE))),"") | H13: =IF(AND(F13<>"",G13<>""),F13*G13,"") | I13: =IFERROR(H13-(F13*VLOOKUP(E13,'04_PRODUCTOS'!B:D,3,FALSE)),"") | J13: =IFERROR(I13/H13,"")
A14: =IF(C14="","","VEN"&TEXT(ROW()-1,"000000")) | B14: =IF(C14="","",TODAY()) | G14: =IFERROR(IF(D14="Mayorista",IF(VLOOKUP(E14,'04_PRODUCTOS'!B:F,5,FALSE)="",VLOOKUP(E14,'04_PRODUCTOS'!B:E,4,FALSE),VLOOKUP(E14,'04_PRODUCTOS'!B:F,5,FALSE)),IF(D14="Especial",IF(VLOOKUP(E14,'04_PRODUCTOS'!B:G,6,FALSE)="",VLOOKUP(E14,'04_PRODUCTOS'!B:E,4,FALSE),VLOOKUP(E14,'04_PRODUCTOS'!B:G,6,FALSE)),VLOOKUP(E14,'04_PRODUCTOS'!B:E,4,FALSE))),"") | H14: =IF(AND(F14<>"",G14<>""),F14*G14,"") | I14: =IFERROR(H14-(F14*VLOOKUP(E14,'04_PRODUCTOS'!B:D,3,FALSE)),"") | J14: =IFERROR(I14/H14,"")
A15: =IF(C15="","","VEN"&TEXT(ROW()-1,"000000")) | B15: =IF(C15="","",TODAY()) | G15: =IFERROR(IF(D15="Mayorista",IF(VLOOKUP(E15,'04_PRODUCTOS'!B:F,5,FALSE)="",VLOOKUP(E15,'04_PRODUCTOS'!B:E,4,FALSE),VLOOKUP(E15,'04_PRODUCTOS'!B:F,5,FALSE)),IF(D15="Especial",IF(VLOOKUP(E15,'04_PRODUCTOS'!B:G,6,FALSE)="",VLOOKUP(E15,'04_PRODUCTOS'!B:E,4,FALSE),VLOOKUP(E15,'04_PRODUCTOS'!B:G,6,FALSE)),VLOOKUP(E15,'04_PRODUCTOS'!B:E,4,FALSE))),"") | H15: =IF(AND(F15<>"",G15<>""),F15*G15,"") | I15: =IFERROR(H15-(F15*VLOOKUP(E15,'04_PRODUCTOS'!B:D,3,FALSE)),"") | J15: =IFERROR(I15/H15,"")
A16: =IF(C16="","","VEN"&TEXT(ROW()-1,"000000")) | B16: =IF(C16="","",TODAY()) | G16: =IFERROR(IF(D16="Mayorista",IF(VLOOKUP(E16,'04_PRODUCTOS'!B:F,5,FALSE)="",VLOOKUP(E16,'04_PRODUCTOS'!B:E,4,FALSE),VLOOKUP(E16,'04_PRODUCTOS'!B:F,5,FALSE)),IF(D16="Especial",IF(VLOOKUP(E16,'04_PRODUCTOS'!B:G,6,FALSE)="",VLOOKUP(E16,'04_PRODUCTOS'!B:E,4,FALSE),VLOOKUP(E16,'04_PRODUCTOS'!B:G,6,FALSE)),VLOOKUP(E16,'04_PRODUCTOS'!B:E,4,FALSE))),"") | H16: =IF(AND(F16<>"",G16<>""),F16*G16,"") | I16: =IFERROR(H16-(F16*VLOOKUP(E16,'04_PRODUCTOS'!B:D,3,FALSE)),"") | J16: =IFERROR(I16/H16,"")
A17: =IF(C17="","","VEN"&TEXT(ROW()-1,"000000")) | B17: =IF(C17="","",TODAY()) | G17: =IFERROR(IF(D17="Mayorista",IF(VLOOKUP(E17,'04_PRODUCTOS'!B:F,5,FALSE)="",VLOOKUP(E17,'04_PRODUCTOS'!B:E,4,FALSE),VLOOKUP(E17,'04_PRODUCTOS'!B:F,5,FALSE)),IF(D17="Especial",IF(VLOOKUP(E17,'04_PRODUCTOS'!B:G,6,FALSE)="",VLOOKUP(E17,'04_PRODUCTOS'!B:E,4,FALSE),VLOOKUP(E17,'04_PRODUCTOS'!B:G,6,FALSE)),VLOOKUP(E17,'04_PRODUCTOS'!B:E,4,FALSE))),"") | H17: =IF(AND(F17<>"",G17<>""),F17*G17,"") | I17: =IFERROR(H17-(F17*VLOOKUP(E17,'04_PRODUCTOS'!B:D,3,FALSE)),"") | J17: =IFERROR(I17/H17,"")
A18: =IF(C18="","","VEN"&TEXT(ROW()-1,"000000")) | B18: =IF(C18="","",TODAY()) | G18: =IFERROR(IF(D18="Mayorista",IF(VLOOKUP(E18,'04_PRODUCTOS'!B:F,5,FALSE)="",VLOOKUP(E18,'04_PRODUCTOS'!B:E,4,FALSE),VLOOKUP(E18,'04_PRODUCTOS'!B:F,5,FALSE)),IF(D18="Especial",IF(VLOOKUP(E18,'04_PRODUCTOS'!B:G,6,FALSE)="",VLOOKUP(E18,'04_PRODUCTOS'!B:E,4,FALSE),VLOOKUP(E18,'04_PRODUCTOS'!B:G,6,FALSE)),VLOOKUP(E18,'04_PRODUCTOS'!B:E,4,FALSE))),"") | H18: =IF(AND(F18<>"",G18<>""),F18*G18,"") | I18: =IFERROR(H18-(F18*VLOOKUP(E18,'04_PRODUCTOS'!B:D,3,FALSE)),"") | J18: =IFERROR(I18/H18,"")
A19: =IF(C19="","","VEN"&TEXT(ROW()-1,"000000")) | B19: =IF(C19="","",TODAY()) | G19: =IFERROR(IF(D19="Mayorista",IF(VLOOKUP(E19,'04_PRODUCTOS'!B:F,5,FALSE)="",VLOOKUP(E19,'04_PRODUCTOS'!B:E,4,FALSE),VLOOKUP(E19,'04_PRODUCTOS'!B:F,5,FALSE)),IF(D19="Especial",IF(VLOOKUP(E19,'04_PRODUCTOS'!B:G,6,FALSE)="",VLOOKUP(E19,'04_PRODUCTOS'!B:E,4,FALSE),VLOOKUP(E19,'04_PRODUCTOS'!B:G,6,FALSE)),VLOOKUP(E19,'04_PRODUCTOS'!B:E,4,FALSE))),"") | H19: =IF(AND(F19<>"",G19<>""),F19*G19,"") | I19: =IFERROR(H19-(F19*VLOOKUP(E19,'04_PRODUCTOS'!B:D,3,FALSE)),"") | J19: =IFERROR(I19/H19,"")
A20: =IF(C20="","","VEN"&TEXT(ROW()-1,"000000")) | B20: =IF(C20="","",TODAY()) | G20: =IFERROR(IF(D20="Mayorista",IF(VLOOKUP(E20,'04_PRODUCTOS'!B:F,5,FALSE)="",VLOOKUP(E20,'04_PRODUCTOS'!B:E,4,FALSE),VLOOKUP(E20,'04_PRODUCTOS'!B:F,5,FALSE)),IF(D20="Especial",IF(VLOOKUP(E20,'04_PRODUCTOS'!B:G,6,FALSE)="",VLOOKUP(E20,'04_PRODUCTOS'!B:E,4,FALSE),VLOOKUP(E20,'04_PRODUCTOS'!B:G,6,FALSE)),VLOOKUP(E20,'04_PRODUCTOS'!B:E,4,FALSE))),"") | H20: =IF(AND(F20<>"",G20<>""),F20*G20,"") | I20: =IFERROR(H20-(F20*VLOOKUP(E20,'04_PRODUCTOS'!B:D,3,FALSE)),"") | J20: =IFERROR(I20/H20,"")
A21: =IF(C21="","","VEN"&TEXT(ROW()-1,"000000")) | B21: =IF(C21="","",TODAY()) | G21: =IFERROR(IF(D21="Mayorista",IF(VLOOKUP(E21,'04_PRODUCTOS'!B:F,5,FALSE)="",VLOOKUP(E21,'04_PRODUCTOS'!B:E,4,FALSE),VLOOKUP(E21,'04_PRODUCTOS'!B:F,5,FALSE)),IF(D21="Especial",IF(VLOOKUP(E21,'04_PRODUCTOS'!B:G,6,FALSE)="",VLOOKUP(E21,'04_PRODUCTOS'!B:E,4,FALSE),VLOOKUP(E21,'04_PRODUCTOS'!B:G,6,FALSE)),VLOOKUP(E21,'04_PRODUCTOS'!B:E,4,FALSE))),"") | H21: =IF(AND(F21<>"",G21<>""),F21*G21,"") | I21: =IFERROR(H21-(F21*VLOOKUP(E21,'04_PRODUCTOS'!B:D,3,FALSE)),"") | J21: =IFERROR(I21/H21,"")
... A101: =IF(C101="","","VEN"&TEXT(ROW()-1,"000000")) | B101: =IF(C101="","",TODAY()) | G101: =IFERROR(IF(D101="Mayorista",IF(VLOOKUP(E101,'04_PRODUCTOS'!B:F,5,FALSE)="",VLOOKUP(E101,'04_PRODUCTOS'!B:E,4,FALSE),VLOOKUP(E101,'04_PRODUCTOS'!B:F,5,FALSE)),IF(D101="Especial",IF(VLOOKUP(E101,'04_PRODUCTOS'!B:G,6,FALSE)="",VLOOKUP(E101,'04_PRODUCTOS'!B:E,4,FALSE),VLOOKUP(E101,'04_PRODUCTOS'!B:G,6,FALSE)),VLOOKUP(E101,'04_PRODUCTOS'!B:E,4,FALSE))),"") | H101: =IF(AND(F101<>"",G101<>""),F101*G101,"") | I101: =IFERROR(H101-(F101*VLOOKUP(E101,'04_PRODUCTOS'!B:D,3,FALSE)),"") | J101: =IFERROR(I101/H101,"")
A102: =IF(C102="","","VEN"&TEXT(ROW()-1,"000000")) | G102: =IFERROR(IF(D102="Mayorista",IF(VLOOKUP(E102,'04_PRODUCTOS'!B:F,5,FALSE)="",VLOOKUP(E102,'04_PRODUCTOS'!B:E,4,FALSE),VLOOKUP(E102,'04_PRODUCTOS'!B:F,5,FALSE)),IF(D102="Especial",IF(VLOOKUP(E102,'04_PRODUCTOS'!B:G,6,FALSE)="",VLOOKUP(E102,'04_PRODUCTOS'!B:E,4,FALSE),VLOOKUP(E102,'04_PRODUCTOS'!B:G,6,FALSE)),VLOOKUP(E102,'04_PRODUCTOS'!B:E,4,FALSE))),"") | H102: =IF(AND(F102<>"",G102<>""),F102*G102,"") | I102: =IFERROR(H102-(F102*VLOOKUP(E102,'04_PRODUCTOS'!B:D,3,FALSE)),"") | J102: =IFERROR(I102/H102,"")
A103: =IF(C103="","","VEN"&TEXT(ROW()-1,"000000")) | G103: =IFERROR(IF(D103="Mayorista",IF(VLOOKUP(E103,'04_PRODUCTOS'!B:F,5,FALSE)="",VLOOKUP(E103,'04_PRODUCTOS'!B:E,4,FALSE),VLOOKUP(E103,'04_PRODUCTOS'!B:F,5,FALSE)),IF(D103="Especial",IF(VLOOKUP(E103,'04_PRODUCTOS'!B:G,6,FALSE)="",VLOOKUP(E103,'04_PRODUCTOS'!B:E,4,FALSE),VLOOKUP(E103,'04_PRODUCTOS'!B:G,6,FALSE)),VLOOKUP(E103,'04_PRODUCTOS'!B:E,4,FALSE))),"") | H103: =IF(AND(F103<>"",G103<>""),F103*G103,"") | I103: =IFERROR(H103-(F103*VLOOKUP(E103,'04_PRODUCTOS'!B:D,3,FALSE)),"") | J103: =IFERROR(I103/H103,"")
A104: =IF(C104="","","VEN"&TEXT(ROW()-1,"000000")) | G104: =IFERROR(IF(D104="Mayorista",IF(VLOOKUP(E104,'04_PRODUCTOS'!B:F,5,FALSE)="",VLOOKUP(E104,'04_PRODUCTOS'!B:E,4,FALSE),VLOOKUP(E104,'04_PRODUCTOS'!B:F,5,FALSE)),IF(D104="Especial",IF(VLOOKUP(E104,'04_PRODUCTOS'!B:G,6,FALSE)="",VLOOKUP(E104,'04_PRODUCTOS'!B:E,4,FALSE),VLOOKUP(E104,'04_PRODUCTOS'!B:G,6,FALSE)),VLOOKUP(E104,'04_PRODUCTOS'!B:E,4,FALSE))),"") | H104: =IF(AND(F104<>"",G104<>""),F104*G104,"") | I104: =IFERROR(H104-(F104*VLOOKUP(E104,'04_PRODUCTOS'!B:D,3,FALSE)),"") | J104: =IFERROR(I104/H104,"")
A105: =IF(C105="","","VEN"&TEXT(ROW()-1,"000000")) | G105: =IFERROR(IF(D105="Mayorista",IF(VLOOKUP(E105,'04_PRODUCTOS'!B:F,5,FALSE)="",VLOOKUP(E105,'04_PRODUCTOS'!B:E,4,FALSE),VLOOKUP(E105,'04_PRODUCTOS'!B:F,5,FALSE)),IF(D105="Especial",IF(VLOOKUP(E105,'04_PRODUCTOS'!B:G,6,FALSE)="",VLOOKUP(E105,'04_PRODUCTOS'!B:E,4,FALSE),VLOOKUP(E105,'04_PRODUCTOS'!B:G,6,FALSE)),VLOOKUP(E105,'04_PRODUCTOS'!B:E,4,FALSE))),"") | H105: =IF(AND(F105<>"",G105<>""),F105*G105,"") | I105: =IFERROR(H105-(F105*VLOOKUP(E105,'04_PRODUCTOS'!B:D,3,FALSE)),"") | J105: =IFERROR(I105/H105,"")
A106: =IF(C106="","","VEN"&TEXT(ROW()-1,"000000")) | G106: =IFERROR(IF(D106="Mayorista",IF(VLOOKUP(E106,'04_PRODUCTOS'!B:F,5,FALSE)="",VLOOKUP(E106,'04_PRODUCTOS'!B:E,4,FALSE),VLOOKUP(E106,'04_PRODUCTOS'!B:F,5,FALSE)),IF(D106="Especial",IF(VLOOKUP(E106,'04_PRODUCTOS'!B:G,6,FALSE)="",VLOOKUP(E106,'04_PRODUCTOS'!B:E,4,FALSE),VLOOKUP(E106,'04_PRODUCTOS'!B:G,6,FALSE)),VLOOKUP(E106,'04_PRODUCTOS'!B:E,4,FALSE))),"") | H106: =IF(AND(F106<>"",G106<>""),F106*G106,"") | I106: =IFERROR(H106-(F106*VLOOKUP(E106,'04_PRODUCTOS'!B:D,3,FALSE)),"") | J106: =IFERROR(I106/H106,"")
A107: =IF(C107="","","VEN"&TEXT(ROW()-1,"000000")) | G107: =IFERROR(IF(D107="Mayorista",IF(VLOOKUP(E107,'04_PRODUCTOS'!B:F,5,FALSE)="",VLOOKUP(E107,'04_PRODUCTOS'!B:E,4,FALSE),VLOOKUP(E107,'04_PRODUCTOS'!B:F,5,FALSE)),IF(D107="Especial",IF(VLOOKUP(E107,'04_PRODUCTOS'!B:G,6,FALSE)="",VLOOKUP(E107,'04_PRODUCTOS'!B:E,4,FALSE),VLOOKUP(E107,'04_PRODUCTOS'!B:G,6,FALSE)),VLOOKUP(E107,'04_PRODUCTOS'!B:E,4,FALSE))),"") | H107: =IF(AND(F107<>"",G107<>""),F107*G107,"") | I107: =IFERROR(H107-(F107*VLOOKUP(E107,'04_PRODUCTOS'!B:D,3,FALSE)),"") | J107: =IFERROR(I107/H107,"")
A108: =IF(C108="","","VEN"&TEXT(ROW()-1,"000000")) | G108: =IFERROR(IF(D108="Mayorista",IF(VLOOKUP(E108,'04_PRODUCTOS'!B:F,5,FALSE)="",VLOOKUP(E108,'04_PRODUCTOS'!B:E,4,FALSE),VLOOKUP(E108,'04_PRODUCTOS'!B:F,5,FALSE)),IF(D108="Especial",IF(VLOOKUP(E108,'04_PRODUCTOS'!B:G,6,FALSE)="",VLOOKUP(E108,'04_PRODUCTOS'!B:E,4,FALSE),VLOOKUP(E108,'04_PRODUCTOS'!B:G,6,FALSE)),VLOOKUP(E108,'04_PRODUCTOS'!B:E,4,FALSE))),"") | H108: =IF(AND(F108<>"",G108<>""),F108*G108,"") | I108: =IFERROR(H108-(F108*VLOOKUP(E108,'04_PRODUCTOS'!B:D,3,FALSE)),"") | J108: =IFERROR(I108/H108,"")
A109: =IF(C109="","","VEN"&TEXT(ROW()-1,"000000")) | G109: =IFERROR(IF(D109="Mayorista",IF(VLOOKUP(E109,'04_PRODUCTOS'!B:F,5,FALSE)="",VLOOKUP(E109,'04_PRODUCTOS'!B:E,4,FALSE),VLOOKUP(E109,'04_PRODUCTOS'!B:F,5,FALSE)),IF(D109="Especial",IF(VLOOKUP(E109,'04_PRODUCTOS'!B:G,6,FALSE)="",VLOOKUP(E109,'04_PRODUCTOS'!B:E,4,FALSE),VLOOKUP(E109,'04_PRODUCTOS'!B:G,6,FALSE)),VLOOKUP(E109,'04_PRODUCTOS'!B:E,4,FALSE))),"") | H109: =IF(AND(F109<>"",G109<>""),F109*G109,"") | I109: =IFERROR(H109-(F109*VLOOKUP(E109,'04_PRODUCTOS'!B:D,3,FALSE)),"") | J109: =IFERROR(I109/H109,"")
A110: =IF(C110="","","VEN"&TEXT(ROW()-1,"000000")) | G110: =IFERROR(IF(D110="Mayorista",IF(VLOOKUP(E110,'04_PRODUCTOS'!B:F,5,FALSE)="",VLOOKUP(E110,'04_PRODUCTOS'!B:E,4,FALSE),VLOOKUP(E110,'04_PRODUCTOS'!B:F,5,FALSE)),IF(D110="Especial",IF(VLOOKUP(E110,'04_PRODUCTOS'!B:G,6,FALSE)="",VLOOKUP(E110,'04_PRODUCTOS'!B:E,4,FALSE),VLOOKUP(E110,'04_PRODUCTOS'!B:G,6,FALSE)),VLOOKUP(E110,'04_PRODUCTOS'!B:E,4,FALSE))),"") | H110: =IF(AND(F110<>"",G110<>""),F110*G110,"") | I110: =IFERROR(H110-(F110*VLOOKUP(E110,'04_PRODUCTOS'!B:D,3,FALSE)),"") | J110: =IFERROR(I110/H110,"")
A111: =IF(C111="","","VEN"&TEXT(ROW()-1,"000000")) | G111: =IFERROR(IF(D111="Mayorista",IF(VLOOKUP(E111,'04_PRODUCTOS'!B:F,5,FALSE)="",VLOOKUP(E111,'04_PRODUCTOS'!B:E,4,FALSE),VLOOKUP(E111,'04_PRODUCTOS'!B:F,5,FALSE)),IF(D111="Especial",IF(VLOOKUP(E111,'04_PRODUCTOS'!B:G,6,FALSE)="",VLOOKUP(E111,'04_PRODUCTOS'!B:E,4,FALSE),VLOOKUP(E111,'04_PRODUCTOS'!B:G,6,FALSE)),VLOOKUP(E111,'04_PRODUCTOS'!B:E,4,FALSE))),"") | H111: =IF(AND(F111<>"",G111<>""),F111*G111,"") | I111: =IFERROR(H111-(F111*VLOOKUP(E111,'04_PRODUCTOS'!B:D,3,FALSE)),"") | J111: =IFERROR(I111/H111,"")
A112: =IF(C112="","","VEN"&TEXT(ROW()-1,"000000")) | G112: =IFERROR(IF(D112="Mayorista",IF(VLOOKUP(E112,'04_PRODUCTOS'!B:F,5,FALSE)="",VLOOKUP(E112,'04_PRODUCTOS'!B:E,4,FALSE),VLOOKUP(E112,'04_PRODUCTOS'!B:F,5,FALSE)),IF(D112="Especial",IF(VLOOKUP(E112,'04_PRODUCTOS'!B:G,6,FALSE)="",VLOOKUP(E112,'04_PRODUCTOS'!B:E,4,FALSE),VLOOKUP(E112,'04_PRODUCTOS'!B:G,6,FALSE)),VLOOKUP(E112,'04_PRODUCTOS'!B:E,4,FALSE))),"") | H112: =IF(AND(F112<>"",G112<>""),F112*G112,"") | I112: =IFERROR(H112-(F112*VLOOKUP(E112,'04_PRODUCTOS'!B:D,3,FALSE)),"") | J112: =IFERROR(I112/H112,"")
A113: =IF(C113="","","VEN"&TEXT(ROW()-1,"000000")) | G113: =IFERROR(IF(D113="Mayorista",IF(VLOOKUP(E113,'04_PRODUCTOS'!B:F,5,FALSE)="",VLOOKUP(E113,'04_PRODUCTOS'!B:E,4,FALSE),VLOOKUP(E113,'04_PRODUCTOS'!B:F,5,FALSE)),IF(D113="Especial",IF(VLOOKUP(E113,'04_PRODUCTOS'!B:G,6,FALSE)="",VLOOKUP(E113,'04_PRODUCTOS'!B:E,4,FALSE),VLOOKUP(E113,'04_PRODUCTOS'!B:G,6,FALSE)),VLOOKUP(E113,'04_PRODUCTOS'!B:E,4,FALSE))),"") | H113: =IF(AND(F113<>"",G113<>""),F113*G113,"") | I113: =IFERROR(H113-(F113*VLOOKUP(E113,'04_PRODUCTOS'!B:D,3,FALSE)),"") | J113: =IFERROR(I113/H113,"")
... A201: =IF(C201="","","VEN"&TEXT(ROW()-1,"000000")) | G201: =IFERROR(IF(D201="Mayorista",IF(VLOOKUP(E201,'04_PRODUCTOS'!B:F,5,FALSE)="",VLOOKUP(E201,'04_PRODUCTOS'!B:E,4,FALSE),VLOOKUP(E201,'04_PRODUCTOS'!B:F,5,FALSE)),IF(D201="Especial",IF(VLOOKUP(E201,'04_PRODUCTOS'!B:G,6,FALSE)="",VLOOKUP(E201,'04_PRODUCTOS'!B:E,4,FALSE),VLOOKUP(E201,'04_PRODUCTOS'!B:G,6,FALSE)),VLOOKUP(E201,'04_PRODUCTOS'!B:E,4,FALSE))),"") | H201: =IF(AND(F201<>"",G201<>""),F201*G201,"") | I201: =IFERROR(H201-(F201*VLOOKUP(E201,'04_PRODUCTOS'!B:D,3,FALSE)),"") | J201: =IFERROR(I201/H201,"")
G202: =IFERROR(IF(D202="Mayorista",IF(VLOOKUP(E202,'04_PRODUCTOS'!B:F,5,FALSE)="",VLOOKUP(E202,'04_PRODUCTOS'!B:E,4,FALSE),VLOOKUP(E202,'04_PRODUCTOS'!B:F,5,FALSE)),IF(D202="Especial",IF(VLOOKUP(E202,'04_PRODUCTOS'!B:G,6,FALSE)="",VLOOKUP(E202,'04_PRODUCTOS'!B:E,4,FALSE),VLOOKUP(E202,'04_PRODUCTOS'!B:G,6,FALSE)),VLOOKUP(E202,'04_PRODUCTOS'!B:E,4,FALSE))),"") | H202: =IF(AND(F202<>"",G202<>""),F202*G202,"") | I202: =IFERROR(H202-(F202*VLOOKUP(E202,'04_PRODUCTOS'!B:D,3,FALSE)),"") | J202: =IFERROR(I202/H202,"")
G203: =IFERROR(IF(D203="Mayorista",IF(VLOOKUP(E203,'04_PRODUCTOS'!B:F,5,FALSE)="",VLOOKUP(E203,'04_PRODUCTOS'!B:E,4,FALSE),VLOOKUP(E203,'04_PRODUCTOS'!B:F,5,FALSE)),IF(D203="Especial",IF(VLOOKUP(E203,'04_PRODUCTOS'!B:G,6,FALSE)="",VLOOKUP(E203,'04_PRODUCTOS'!B:E,4,FALSE),VLOOKUP(E203,'04_PRODUCTOS'!B:G,6,FALSE)),VLOOKUP(E203,'04_PRODUCTOS'!B:E,4,FALSE))),"") | H203: =IF(AND(F203<>"",G203<>""),F203*G203,"") | I203: =IFERROR(H203-(F203*VLOOKUP(E203,'04_PRODUCTOS'!B:D,3,FALSE)),"") | J203: =IFERROR(I203/H203,"")
G204: =IFERROR(IF(D204="Mayorista",IF(VLOOKUP(E204,'04_PRODUCTOS'!B:F,5,FALSE)="",VLOOKUP(E204,'04_PRODUCTOS'!B:E,4,FALSE),VLOOKUP(E204,'04_PRODUCTOS'!B:F,5,FALSE)),IF(D204="Especial",IF(VLOOKUP(E204,'04_PRODUCTOS'!B:G,6,FALSE)="",VLOOKUP(E204,'04_PRODUCTOS'!B:E,4,FALSE),VLOOKUP(E204,'04_PRODUCTOS'!B:G,6,FALSE)),VLOOKUP(E204,'04_PRODUCTOS'!B:E,4,FALSE))),"") | H204: =IF(AND(F204<>"",G204<>""),F204*G204,"") | I204: =IFERROR(H204-(F204*VLOOKUP(E204,'04_PRODUCTOS'!B:D,3,FALSE)),"") | J204: =IFERROR(I204/H204,"")
G205: =IFERROR(IF(D205="Mayorista",IF(VLOOKUP(E205,'04_PRODUCTOS'!B:F,5,FALSE)="",VLOOKUP(E205,'04_PRODUCTOS'!B:E,4,FALSE),VLOOKUP(E205,'04_PRODUCTOS'!B:F,5,FALSE)),IF(D205="Especial",IF(VLOOKUP(E205,'04_PRODUCTOS'!B:G,6,FALSE)="",VLOOKUP(E205,'04_PRODUCTOS'!B:E,4,FALSE),VLOOKUP(E205,'04_PRODUCTOS'!B:G,6,FALSE)),VLOOKUP(E205,'04_PRODUCTOS'!B:E,4,FALSE))),"") | H205: =IF(AND(F205<>"",G205<>""),F205*G205,"") | I205: =IFERROR(H205-(F205*VLOOKUP(E205,'04_PRODUCTOS'!B:D,3,FALSE)),"") | J205: =IFERROR(I205/H205,"")
G206: =IFERROR(IF(D206="Mayorista",IF(VLOOKUP(E206,'04_PRODUCTOS'!B:F,5,FALSE)="",VLOOKUP(E206,'04_PRODUCTOS'!B:E,4,FALSE),VLOOKUP(E206,'04_PRODUCTOS'!B:F,5,FALSE)),IF(D206="Especial",IF(VLOOKUP(E206,'04_PRODUCTOS'!B:G,6,FALSE)="",VLOOKUP(E206,'04_PRODUCTOS'!B:E,4,FALSE),VLOOKUP(E206,'04_PRODUCTOS'!B:G,6,FALSE)),VLOOKUP(E206,'04_PRODUCTOS'!B:E,4,FALSE))),"") | H206: =IF(AND(F206<>"",G206<>""),F206*G206,"") | I206: =IFERROR(H206-(F206*VLOOKUP(E206,'04_PRODUCTOS'!B:D,3,FALSE)),"") | J206: =IFERROR(I206/H206,"")
...

Sheet 12_VERSION
A1: Versión | B1: 0.3.5
A2: Build | B2: Corrección e integración del motor de precios

Sheet 10_DASHBOARD
A1: CARNE PREMIUM ERP — DASHBOARD
D2: Mes | E2: Facturación | F2: Ganancia
A3: Ventas registradas | B3: =COUNTA('05_VENTAS'!A2:A501) -> 200 | D3: 1 | E3: =SUMPRODUCT((MONTH('05_VENTAS'!$B$2:$B$501)=D3)*('05_VENTAS'!$H$2:$H$501)) -> #VALUE! | F3: =SUMPRODUCT((MONTH('05_VENTAS'!$B$2:$B$501)=D3)*('05_VENTAS'!$I$2:$I$501)) -> #VALUE!
A4: Facturación | B4: =SUM('05_VENTAS'!H2:H501) -> 612600 | D4: 2 | E4: =SUMPRODUCT((MONTH('05_VENTAS'!$B$2:$B$501)=D4)*('05_VENTAS'!$H$2:$H$501)) -> #VALUE! | F4: =SUMPRODUCT((MONTH('05_VENTAS'!$B$2:$B$501)=D4)*('05_VENTAS'!$I$2:$I$501)) -> #VALUE!
A5: Ganancia | B5: =SUM('05_VENTAS'!I2:I501) -> 67000 | D5: 3 | E5: =SUMPRODUCT((MONTH('05_VENTAS'!$B$2:$B$501)=D5)*('05_VENTAS'!$H$2:$H$501)) -> #VALUE! | F5: =SUMPRODUCT((MONTH('05_VENTAS'!$B$2:$B$501)=D5)*('05_VENTAS'!$I$2:$I$501)) -> #VALUE!
A6: Margen | B6: =IFERROR(B5/B4,"") -> 0.1093699 | D6: 4 | E6: =SUMPRODUCT((MONTH('05_VENTAS'!$B$2:$B$501)=D6)*('05_VENTAS'!$H$2:$H$501)) -> #VALUE! | F6: =SUMPRODUCT((MONTH('05_VENTAS'!$B$2:$B$501)=D6)*('05_VENTAS'!$I$2:$I$501)) -> #VALUE!
A7: Kg vendidos | B7: =SUM('05_VENTAS'!F2:F501) -> 26.8 | D7: 5 | E7: =SUMPRODUCT((MONTH('05_VENTAS'!$B$2:$B$501)=D7)*('05_VENTAS'!$H$2:$H$501)) -> #VALUE! | F7: =SUMPRODUCT((MONTH('05_VENTAS'!$B$2:$B$501)=D7)*('05_VENTAS'!$I$2:$I$501)) -> #VALUE!
A8: Ticket promedio | B8: =IFERROR(B4/B3,"") -> 3063 | D8: 6 | E8: =SUMPRODUCT((MONTH('05_VENTAS'!$B$2:$B$501)=D8)*('05_VENTAS'!$H$2:$H$501)) -> #VALUE! | F8: =SUMPRODUCT((MONTH('05_VENTAS'!$B$2:$B$501)=D8)*('05_VENTAS'!$I$2:$I$501)) -> #VALUE!
D9: 7 | E9: =SUMPRODUCT((MONTH('05_VENTAS'!$B$2:$B$501)=D9)*('05_VENTAS'!$H$2:$H$501)) -> #VALUE! | F9: =SUMPRODUCT((MONTH('05_VENTAS'!$B$2:$B$501)=D9)*('05_VENTAS'!$I$2:$I$501)) -> #VALUE!
D10: 8 | E10: =SUMPRODUCT((MONTH('05_VENTAS'!$B$2:$B$501)=D10)*('05_VENTAS'!$H$2:$H$501)) -> #VALUE! | F10: =SUMPRODUCT((MONTH('05_VENTAS'!$B$2:$B$501)=D10)*('05_VENTAS'!$I$2:$I$501)) -> #VALUE!
D11: 9 | E11: =SUMPRODUCT((MONTH('05_VENTAS'!$B$2:$B$501)=D11)*('05_VENTAS'!$H$2:$H$501)) -> #VALUE! | F11: =SUMPRODUCT((MONTH('05_VENTAS'!$B$2:$B$501)=D11)*('05_VENTAS'!$I$2:$I$501)) -> #VALUE!
D12: 10 | E12: =SUMPRODUCT((MONTH('05_VENTAS'!$B$2:$B$501)=D12)*('05_VENTAS'!$H$2:$H$501)) -> #VALUE! | F12: =SUMPRODUCT((MONTH('05_VENTAS'!$B$2:$B$501)=D12)*('05_VENTAS'!$I$2:$I$501)) -> #VALUE!
D13: 11 | E13: =SUMPRODUCT((MONTH('05_VENTAS'!$B$2:$B$501)=D13)*('05_VENTAS'!$H$2:$H$501)) -> #VALUE! | F13: =SUMPRODUCT((MONTH('05_VENTAS'!$B$2:$B$501)=D13)*('05_VENTAS'!$I$2:$I$501)) -> #VALUE!
D14: 12 | E14: =SUMPRODUCT((MONTH('05_VENTAS'!$B$2:$B$501)=D14)*('05_VENTAS'!$H$2:$H$501)) -> #VALUE! | F14: =SUMPRODUCT((MONTH('05_VENTAS'!$B$2:$B$501)=D14)*('05_VENTAS'!$I$2:$I$501)) -> #VALUE!

Sheet 06_TICKET
A1: CARNE PREMIUM — TICKET
A3: VentaID | B3: ='05_VENTAS'!A2 -> VEN000001
A4: Fecha | B4: ='05_VENTAS'!B2 -> 46204
A5: Cliente | B5: ='05_VENTAS'!C2 -> Pato O'Reilly
A7: Corte | B7: ='05_VENTAS'!E2 -> Picada Especial
A8: Kg | B8: ='05_VENTAS'!F2 -> 3.4
A9: Precio/Kg | B9: ='05_VENTAS'!G2 -> 16000
A10: Total | B10: ='05_VENTAS'!H2 -> 54400

Sheet 22_PRECIOS
A1: PrecioID | B1: ProductoID | C1: ClienteID | D1: TipoPrecio | E1: PrecioKg | F1: FechaInicio | G1: FechaFin | H1: Prioridad | I1: Estado | J1: Motivo
H2: =IF(D2="Especial",1,IF(D2="Mayorista",2,3)) -> 3
H3: =IF(D3="Especial",1,IF(D3="Mayorista",2,3)) -> 3
H4: =IF(D4="Especial",1,IF(D4="Mayorista",2,3)) -> 3
H5: =IF(D5="Especial",1,IF(D5="Mayorista",2,3)) -> 3
H6: =IF(D6="Especial",1,IF(D6="Mayorista",2,3)) -> 3
H7: =IF(D7="Especial",1,IF(D7="Mayorista",2,3)) -> 3
H8: =IF(D8="Especial",1,IF(D8="Mayorista",2,3)) -> 3
H9: =IF(D9="Especial",1,IF(D9="Mayorista",2,3)) -> 3
H10: =IF(D10="Especial",1,IF(D10="Mayorista",2,3)) -> 3
H11: =IF(D11="Especial",1,IF(D11="Mayorista",2,3)) -> 3
H12: =IF(D12="Especial",1,IF(D12="Mayorista",2,3)) -> 3
H13: =IF(D13="Especial",1,IF(D13="Mayorista",2,3)) -> 3
... H501: =IF(D501="Especial",1,IF(D501="Mayorista",2,3)) -> 3

Sheet 23_OFERTAS
A1: OfertaID | B1: ProductoID | C1: NombreOferta | D1: PrecioOferta | E1: Descuento% | F1: FechaInicio | G1: FechaFin | H1: MinKg | I1: Estado | J1: Prioridad

Sheet 21_HISTORICO_PRECIOS
A1: Fecha | B1: ProductoID | C1: ClienteID | D1: TipoPrecio | E1: PrecioAnterior | F1: PrecioNuevo | G1: Motivo | H1: Usuario
